<?xml version="1.0"?>
<robot xmlns:xacro="http://ros.org/wiki/xacro">
    
  <!-- Robot Wheel -->
  <xacro:macro name="link_wheel" params="name">
    <link name="${name}">
      <inertial>
        <mass value="0.2"/>
        <origin rpy="0 1.5707 1.5707" xyz="0 0 0"/>
        <inertia ixx="0.000526666666667" ixy="0" ixz="0" 
                       iyy="0.000526666666667" iyz="0" izz="0.001"/>
      </inertial>
      <collision name="${name}_collision">
        <origin rpy="0 1.5707 1.5707" xyz="0 0 0"/>
        <geometry>
          <cylinder length="0.04" radius="0.1"/>
        </geometry>
      </collision>
      <visual name="${name}_visual">
        <origin rpy="0 1.5707 1.5707" xyz="0 0 0"/>
        <geometry>
          <cylinder length="0.04" radius="0.1"/>
        </geometry>
      </visual>
    </link>
  </xacro:macro>

  <xacro:macro name="joint_wheel" params="name child origin_xyz">
    <joint name="${name}" type="continuous">
      <origin rpy="0 0 0" xyz="${origin_xyz}"/>
      <child link="${child}"/>
      <parent link="link_chassis"/>
      <axis rpy="0 0 0" xyz="0 1 0"/>
      <limit effort="10000" velocity="1000"/>
      <joint_properties damping="1.0" friction="1.0"/>
    </joint>
  </xacro:macro>
    
  <xacro:macro name="trans_wheel" params="name joint">
    <transmission name="${name}">
      <type>transmission_interface/SimpleTransmission</type>
      <joint name="${joint}">
        <hardwareInterface>hardware_interface/VelocityJointInterface</hardwareInterface>  
      </joint>
      <actuator name="${name}_actuator">
        <mechanicalReduction>7</mechanicalReduction>
        <hardwareInterface>VelocityJointInterface</hardwareInterface>
      </actuator>
    </transmission>
  </xacro:macro>
  
  <!-- Stereo Camera -->
  <xacro:macro name="link_camera" params="name direction_rpy">
    <link name="${name}">
      <inertial>
        <mass value="0.1"/>
        <origin rpy="${direction_rpy}" xyz="0 0 0"/>
        <box_inertia m="0.1" x="0.05" y="0.05" z="0.05" />
        <inertia ixx="1e-6" ixy="0" ixz="0" 
                 iyy="1e-6" iyz="0" izz="1e-6"/>
      </inertial>
      <collision name="${name}_collision">
        <origin rpy="${direction_rpy}" xyz="0 0 0"/>
        <geometry>
          <box size="0.05 0.05 0.05" />
        </geometry>
      </collision>
      <visual name="${name}_visual">
        <origin rpy="${direction_rpy}" xyz="0 0 0"/>
        <geometry>
          <box size="0.05 0.1 0.05" />
        </geometry>
      </visual>
    </link>
  </xacro:macro>
  
  <xacro:macro name="joint_camera" params="name child origin_xyz">
    <joint name="${name}" type="fixed">
      <axis xyz="0 1 0"/>
      <origin rpy="0 0 0" xyz="${origin_xyz}"/>
      <child link="${child}"/>
      <parent link="link_chassis"/>
    </joint>
  </xacro:macro>
    
</robot>
